[2022-02-06 18:18:42,113] {taskinstance.py:1026} INFO - Dependencies not met for <TaskInstance: fhv_data_dag.download_fhv_dataset_task scheduled__2019-09-02T06:00:00+00:00 [queued]>, dependency 'Execution Date' FAILED: The execution date is 2019-09-02T06:00:00+00:00 but this is after the task's end date 2019-09-02T00:00:00+00:00.
[2022-02-06 18:18:42,114] {taskinstance.py:1026} INFO - Dependencies not met for <TaskInstance: fhv_data_dag.download_fhv_dataset_task scheduled__2019-09-02T06:00:00+00:00 [queued]>, dependency 'Execution Date' FAILED: The execution date is 2019-09-02T06:00:00+00:00 but this is after the task's DAG's end date 2019-09-02T00:00:00+00:00.
[2022-02-06 18:18:42,119] {local_task_job.py:99} INFO - Task is not able to be run
[2022-02-06 18:22:14,471] {taskinstance.py:1032} INFO - Dependencies all met for <TaskInstance: fhv_data_dag.download_fhv_dataset_task scheduled__2019-09-02T06:00:00+00:00 [queued]>
[2022-02-06 18:22:14,486] {taskinstance.py:1032} INFO - Dependencies all met for <TaskInstance: fhv_data_dag.download_fhv_dataset_task scheduled__2019-09-02T06:00:00+00:00 [queued]>
[2022-02-06 18:22:14,486] {taskinstance.py:1238} INFO - 
--------------------------------------------------------------------------------
[2022-02-06 18:22:14,487] {taskinstance.py:1239} INFO - Starting attempt 8 of 9
[2022-02-06 18:22:14,487] {taskinstance.py:1240} INFO - 
--------------------------------------------------------------------------------
[2022-02-06 18:22:14,506] {taskinstance.py:1259} INFO - Executing <Task(BashOperator): download_fhv_dataset_task> on 2019-09-02 06:00:00+00:00
[2022-02-06 18:22:14,512] {standard_task_runner.py:52} INFO - Started process 1998 to run task
[2022-02-06 18:22:14,518] {standard_task_runner.py:76} INFO - Running: ['***', 'tasks', 'run', 'fhv_data_dag', 'download_fhv_dataset_task', 'scheduled__2019-09-02T06:00:00+00:00', '--job-id', '266', '--raw', '--subdir', 'DAGS_FOLDER/fhv_data_dag.py', '--cfg-path', '/tmp/tmpykce9nw0', '--error-file', '/tmp/tmpbxwjdcq9']
[2022-02-06 18:22:14,520] {standard_task_runner.py:77} INFO - Job 266: Subtask download_fhv_dataset_task
[2022-02-06 18:22:14,610] {logging_mixin.py:109} INFO - Running <TaskInstance: fhv_data_dag.download_fhv_dataset_task scheduled__2019-09-02T06:00:00+00:00 [running]> on host c0c5e0341789
[2022-02-06 18:22:14,685] {warnings.py:110} WARNING - /home/***/.local/lib/python3.7/site-packages/***/utils/context.py:152: AirflowContextDeprecationWarning: Accessing 'execution_date' from the template is deprecated and will be removed in a future version. Please use 'data_interval_start' or 'logical_date' instead.
  warnings.warn(_create_deprecation_warning(key, self._deprecation_replacements[key]))

[2022-02-06 18:22:14,709] {taskinstance.py:1426} INFO - Exporting the following env vars:
AIRFLOW_CTX_DAG_OWNER=***
AIRFLOW_CTX_DAG_ID=fhv_data_dag
AIRFLOW_CTX_TASK_ID=download_fhv_dataset_task
AIRFLOW_CTX_EXECUTION_DATE=2019-09-02T06:00:00+00:00
AIRFLOW_CTX_DAG_RUN_ID=scheduled__2019-09-02T06:00:00+00:00
[2022-02-06 18:22:14,710] {subprocess.py:62} INFO - Tmp dir root location: 
 /tmp
[2022-02-06 18:22:14,711] {subprocess.py:74} INFO - Running command: ['bash', '-c', 'curl -sSLf https://nyc-tlc.s3.amazonaws.com/trip+data/fhv_tripdata_2019-09.csv > /opt/***/fhv_tripdata_2019-09.csv']
[2022-02-06 18:22:14,725] {subprocess.py:85} INFO - Output:
[2022-02-06 18:27:11,322] {subprocess.py:89} INFO - curl: (18) transfer closed with 23554334 bytes remaining to read
[2022-02-06 18:27:11,325] {subprocess.py:93} INFO - Command exited with return code 18
[2022-02-06 18:27:11,352] {taskinstance.py:1700} ERROR - Task failed with exception
Traceback (most recent call last):
  File "/home/airflow/.local/lib/python3.7/site-packages/airflow/models/taskinstance.py", line 1329, in _run_raw_task
    self._execute_task_with_callbacks(context)
  File "/home/airflow/.local/lib/python3.7/site-packages/airflow/models/taskinstance.py", line 1455, in _execute_task_with_callbacks
    result = self._execute_task(context, self.task)
  File "/home/airflow/.local/lib/python3.7/site-packages/airflow/models/taskinstance.py", line 1511, in _execute_task
    result = execute_callable(context=context)
  File "/home/airflow/.local/lib/python3.7/site-packages/airflow/operators/bash.py", line 188, in execute
    f'Bash command failed. The command returned a non-zero exit code {result.exit_code}.'
airflow.exceptions.AirflowException: Bash command failed. The command returned a non-zero exit code 18.
[2022-02-06 18:27:11,366] {taskinstance.py:1277} INFO - Marking task as UP_FOR_RETRY. dag_id=fhv_data_dag, task_id=download_fhv_dataset_task, execution_date=20190902T060000, start_date=20220206T182214, end_date=20220206T182711
[2022-02-06 18:27:11,394] {standard_task_runner.py:92} ERROR - Failed to execute job 266 for task download_fhv_dataset_task
Traceback (most recent call last):
  File "/home/airflow/.local/lib/python3.7/site-packages/airflow/task/task_runner/standard_task_runner.py", line 85, in _start_by_fork
    args.func(args, dag=self.dag)
  File "/home/airflow/.local/lib/python3.7/site-packages/airflow/cli/cli_parser.py", line 48, in command
    return func(*args, **kwargs)
  File "/home/airflow/.local/lib/python3.7/site-packages/airflow/utils/cli.py", line 92, in wrapper
    return f(*args, **kwargs)
  File "/home/airflow/.local/lib/python3.7/site-packages/airflow/cli/commands/task_command.py", line 298, in task_run
    _run_task_by_selected_method(args, dag, ti)
  File "/home/airflow/.local/lib/python3.7/site-packages/airflow/cli/commands/task_command.py", line 107, in _run_task_by_selected_method
    _run_raw_task(args, ti)
  File "/home/airflow/.local/lib/python3.7/site-packages/airflow/cli/commands/task_command.py", line 184, in _run_raw_task
    error_file=args.error_file,
  File "/home/airflow/.local/lib/python3.7/site-packages/airflow/utils/session.py", line 70, in wrapper
    return func(*args, session=session, **kwargs)
  File "/home/airflow/.local/lib/python3.7/site-packages/airflow/models/taskinstance.py", line 1329, in _run_raw_task
    self._execute_task_with_callbacks(context)
  File "/home/airflow/.local/lib/python3.7/site-packages/airflow/models/taskinstance.py", line 1455, in _execute_task_with_callbacks
    result = self._execute_task(context, self.task)
  File "/home/airflow/.local/lib/python3.7/site-packages/airflow/models/taskinstance.py", line 1511, in _execute_task
    result = execute_callable(context=context)
  File "/home/airflow/.local/lib/python3.7/site-packages/airflow/operators/bash.py", line 188, in execute
    f'Bash command failed. The command returned a non-zero exit code {result.exit_code}.'
airflow.exceptions.AirflowException: Bash command failed. The command returned a non-zero exit code 18.
[2022-02-06 18:27:11,421] {local_task_job.py:154} INFO - Task exited with return code 1
[2022-02-06 18:27:11,490] {local_task_job.py:264} INFO - 0 downstream tasks scheduled from follow-on schedule check
